Waiting for at least one worker...
[                                        ] | 0% Completed |  0.1s[                                        ] | 0% Completed |  0.2s[                                        ] | 0% Completed |  0.3s[                                        ] | 0% Completed |  3min 12.5s[                                        ] | 1% Completed |  3min 12.6s[                                        ] | 1% Completed |  3min 12.7s[                                        ] | 1% Completed |  3min 12.8s[                                        ] | 1% Completed |  3min 12.9s[                                        ] | 1% Completed |  3min 13.0s[                                        ] | 1% Completed |  3min 13.1s[                                        ] | 1% Completed |  3min 13.2s[                                        ] | 1% Completed |  3min 13.5s[                                        ] | 1% Completed |  3min 13.6s[                                        ] | 1% Completed |  3min 13.7s[                                        ] | 1% Completed |  3min 13.8s[                                        ] | 1% Completed |  3min 13.9s[                                        ] | 1% Completed |  3min 14.0s[                                        ] | 1% Completed | 32min 23.3s[                                        ] | 1% Completed | 32min 23.8sdistributed.core - ERROR - 'tcp://131.225.204.101:10000'
Traceback (most recent call last):
  File "/opt/conda/lib/python3.8/site-packages/distributed/core.py", line 571, in handle_stream
    handler(**merge(extra, msg))
  File "/opt/conda/lib/python3.8/site-packages/distributed/scheduler.py", line 5089, in handle_release_data
    ws: WorkerState = parent._workers_dv[worker]
KeyError: 'tcp://131.225.204.101:10000'
distributed.utils - ERROR - 'tcp://131.225.204.101:10000'
Traceback (most recent call last):
  File "/opt/conda/lib/python3.8/site-packages/distributed/utils.py", line 650, in log_errors
    yield
  File "/opt/conda/lib/python3.8/site-packages/distributed/scheduler.py", line 4099, in add_worker
    await self.handle_worker(comm=comm, worker=address)
  File "/opt/conda/lib/python3.8/site-packages/distributed/scheduler.py", line 5189, in handle_worker
    await self.handle_stream(comm=comm, extra={"worker": worker})
  File "/opt/conda/lib/python3.8/site-packages/distributed/core.py", line 571, in handle_stream
    handler(**merge(extra, msg))
  File "/opt/conda/lib/python3.8/site-packages/distributed/scheduler.py", line 5089, in handle_release_data
    ws: WorkerState = parent._workers_dv[worker]
KeyError: 'tcp://131.225.204.101:10000'
distributed.core - ERROR - 'tcp://131.225.191.137:10000'
Traceback (most recent call last):
  File "/opt/conda/lib/python3.8/site-packages/distributed/core.py", line 571, in handle_stream
    handler(**merge(extra, msg))
  File "/opt/conda/lib/python3.8/site-packages/distributed/scheduler.py", line 5089, in handle_release_data
    ws: WorkerState = parent._workers_dv[worker]
KeyError: 'tcp://131.225.191.137:10000'
distributed.utils - ERROR - 'tcp://131.225.191.137:10000'
Traceback (most recent call last):
  File "/opt/conda/lib/python3.8/site-packages/distributed/utils.py", line 650, in log_errors
    yield
  File "/opt/conda/lib/python3.8/site-packages/distributed/scheduler.py", line 4099, in add_worker
    await self.handle_worker(comm=comm, worker=address)
  File "/opt/conda/lib/python3.8/site-packages/distributed/scheduler.py", line 5189, in handle_worker
    await self.handle_stream(comm=comm, extra={"worker": worker})
  File "/opt/conda/lib/python3.8/site-packages/distributed/core.py", line 571, in handle_stream
    handler(**merge(extra, msg))
  File "/opt/conda/lib/python3.8/site-packages/distributed/scheduler.py", line 5089, in handle_release_data
    ws: WorkerState = parent._workers_dv[worker]
KeyError: 'tcp://131.225.191.137:10000'
distributed.core - ERROR - 'tcp://131.225.206.197:10000'
Traceback (most recent call last):
  File "/opt/conda/lib/python3.8/site-packages/distributed/core.py", line 571, in handle_stream
    handler(**merge(extra, msg))
  File "/opt/conda/lib/python3.8/site-packages/distributed/scheduler.py", line 5089, in handle_release_data
    ws: WorkerState = parent._workers_dv[worker]
KeyError: 'tcp://131.225.206.197:10000'
distributed.utils - ERROR - 'tcp://131.225.206.197:10000'
Traceback (most recent call last):
  File "/opt/conda/lib/python3.8/site-packages/distributed/utils.py", line 650, in log_errors
    yield
  File "/opt/conda/lib/python3.8/site-packages/distributed/scheduler.py", line 4099, in add_worker
    await self.handle_worker(comm=comm, worker=address)
  File "/opt/conda/lib/python3.8/site-packages/distributed/scheduler.py", line 5189, in handle_worker
    await self.handle_stream(comm=comm, extra={"worker": worker})
  File "/opt/conda/lib/python3.8/site-packages/distributed/core.py", line 571, in handle_stream
    handler(**merge(extra, msg))
  File "/opt/conda/lib/python3.8/site-packages/distributed/scheduler.py", line 5089, in handle_release_data
    ws: WorkerState = parent._workers_dv[worker]
KeyError: 'tcp://131.225.206.197:10000'
distributed.core - ERROR - 'tcp://131.225.204.82:10000'
Traceback (most recent call last):
  File "/opt/conda/lib/python3.8/site-packages/distributed/core.py", line 571, in handle_stream
    handler(**merge(extra, msg))
  File "/opt/conda/lib/python3.8/site-packages/distributed/scheduler.py", line 5089, in handle_release_data
    ws: WorkerState = parent._workers_dv[worker]
KeyError: 'tcp://131.225.204.82:10000'
distributed.utils - ERROR - 'tcp://131.225.204.82:10000'
Traceback (most recent call last):
  File "/opt/conda/lib/python3.8/site-packages/distributed/utils.py", line 650, in log_errors
    yield
  File "/opt/conda/lib/python3.8/site-packages/distributed/scheduler.py", line 4099, in add_worker
    await self.handle_worker(comm=comm, worker=address)
  File "/opt/conda/lib/python3.8/site-packages/distributed/scheduler.py", line 5189, in handle_worker
    await self.handle_stream(comm=comm, extra={"worker": worker})
  File "/opt/conda/lib/python3.8/site-packages/distributed/core.py", line 571, in handle_stream
    handler(**merge(extra, msg))
  File "/opt/conda/lib/python3.8/site-packages/distributed/scheduler.py", line 5089, in handle_release_data
    ws: WorkerState = parent._workers_dv[worker]
KeyError: 'tcp://131.225.204.82:10000'
distributed.core - ERROR - 'tcp://131.225.204.55:10000'
Traceback (most recent call last):
  File "/opt/conda/lib/python3.8/site-packages/distributed/core.py", line 571, in handle_stream
    handler(**merge(extra, msg))
  File "/opt/conda/lib/python3.8/site-packages/distributed/scheduler.py", line 5089, in handle_release_data
    ws: WorkerState = parent._workers_dv[worker]
KeyError: 'tcp://131.225.204.55:10000'
distributed.utils - ERROR - 'tcp://131.225.204.55:10000'
Traceback (most recent call last):
  File "/opt/conda/lib/python3.8/site-packages/distributed/utils.py", line 650, in log_errors
    yield
  File "/opt/conda/lib/python3.8/site-packages/distributed/scheduler.py", line 4099, in add_worker
    await self.handle_worker(comm=comm, worker=address)
  File "/opt/conda/lib/python3.8/site-packages/distributed/scheduler.py", line 5189, in handle_worker
    await self.handle_stream(comm=comm, extra={"worker": worker})
  File "/opt/conda/lib/python3.8/site-packages/distributed/core.py", line 571, in handle_stream
    handler(**merge(extra, msg))
  File "/opt/conda/lib/python3.8/site-packages/distributed/scheduler.py", line 5089, in handle_release_data
    ws: WorkerState = parent._workers_dv[worker]
KeyError: 'tcp://131.225.204.55:10000'
distributed.core - ERROR - 'tcp://131.225.206.38:10000'
Traceback (most recent call last):
  File "/opt/conda/lib/python3.8/site-packages/distributed/core.py", line 571, in handle_stream
    handler(**merge(extra, msg))
  File "/opt/conda/lib/python3.8/site-packages/distributed/scheduler.py", line 5089, in handle_release_data
    ws: WorkerState = parent._workers_dv[worker]
KeyError: 'tcp://131.225.206.38:10000'
distributed.utils - ERROR - 'tcp://131.225.206.38:10000'
Traceback (most recent call last):
  File "/opt/conda/lib/python3.8/site-packages/distributed/utils.py", line 650, in log_errors
    yield
  File "/opt/conda/lib/python3.8/site-packages/distributed/scheduler.py", line 4099, in add_worker
    await self.handle_worker(comm=comm, worker=address)
  File "/opt/conda/lib/python3.8/site-packages/distributed/scheduler.py", line 5189, in handle_worker
    await self.handle_stream(comm=comm, extra={"worker": worker})
  File "/opt/conda/lib/python3.8/site-packages/distributed/core.py", line 571, in handle_stream
    handler(**merge(extra, msg))
  File "/opt/conda/lib/python3.8/site-packages/distributed/scheduler.py", line 5089, in handle_release_data
    ws: WorkerState = parent._workers_dv[worker]
KeyError: 'tcp://131.225.206.38:10000'
distributed.core - ERROR - 'tcp://131.225.206.48:10000'
Traceback (most recent call last):
  File "/opt/conda/lib/python3.8/site-packages/distributed/core.py", line 571, in handle_stream
    handler(**merge(extra, msg))
  File "/opt/conda/lib/python3.8/site-packages/distributed/scheduler.py", line 5089, in handle_release_data
    ws: WorkerState = parent._workers_dv[worker]
KeyError: 'tcp://131.225.206.48:10000'
distributed.utils - ERROR - 'tcp://131.225.206.48:10000'
Traceback (most recent call last):
  File "/opt/conda/lib/python3.8/site-packages/distributed/utils.py", line 650, in log_errors
    yield
  File "/opt/conda/lib/python3.8/site-packages/distributed/scheduler.py", line 4099, in add_worker
    await self.handle_worker(comm=comm, worker=address)
  File "/opt/conda/lib/python3.8/site-packages/distributed/scheduler.py", line 5189, in handle_worker
    await self.handle_stream(comm=comm, extra={"worker": worker})
  File "/opt/conda/lib/python3.8/site-packages/distributed/core.py", line 571, in handle_stream
    handler(**merge(extra, msg))
  File "/opt/conda/lib/python3.8/site-packages/distributed/scheduler.py", line 5089, in handle_release_data
    ws: WorkerState = parent._workers_dv[worker]
KeyError: 'tcp://131.225.206.48:10000'
distributed.core - ERROR - 'tcp://131.225.204.112:10000'
Traceback (most recent call last):
  File "/opt/conda/lib/python3.8/site-packages/distributed/core.py", line 571, in handle_stream
    handler(**merge(extra, msg))
  File "/opt/conda/lib/python3.8/site-packages/distributed/scheduler.py", line 5089, in handle_release_data
    ws: WorkerState = parent._workers_dv[worker]
KeyError: 'tcp://131.225.204.112:10000'
distributed.utils - ERROR - 'tcp://131.225.204.112:10000'
Traceback (most recent call last):
  File "/opt/conda/lib/python3.8/site-packages/distributed/utils.py", line 650, in log_errors
    yield
  File "/opt/conda/lib/python3.8/site-packages/distributed/scheduler.py", line 4099, in add_worker
    await self.handle_worker(comm=comm, worker=address)
  File "/opt/conda/lib/python3.8/site-packages/distributed/scheduler.py", line 5189, in handle_worker
    await self.handle_stream(comm=comm, extra={"worker": worker})
  File "/opt/conda/lib/python3.8/site-packages/distributed/core.py", line 571, in handle_stream
    handler(**merge(extra, msg))
  File "/opt/conda/lib/python3.8/site-packages/distributed/scheduler.py", line 5089, in handle_release_data
    ws: WorkerState = parent._workers_dv[worker]
KeyError: 'tcp://131.225.204.112:10000'
distributed.core - ERROR - 'tcp://131.225.206.177:10000'
Traceback (most recent call last):
  File "/opt/conda/lib/python3.8/site-packages/distributed/core.py", line 571, in handle_stream
    handler(**merge(extra, msg))
  File "/opt/conda/lib/python3.8/site-packages/distributed/scheduler.py", line 5089, in handle_release_data
    ws: WorkerState = parent._workers_dv[worker]
KeyError: 'tcp://131.225.206.177:10000'
distributed.utils - ERROR - 'tcp://131.225.206.177:10000'
Traceback (most recent call last):
  File "/opt/conda/lib/python3.8/site-packages/distributed/utils.py", line 650, in log_errors
    yield
  File "/opt/conda/lib/python3.8/site-packages/distributed/scheduler.py", line 4099, in add_worker
    await self.handle_worker(comm=comm, worker=address)
  File "/opt/conda/lib/python3.8/site-packages/distributed/scheduler.py", line 5189, in handle_worker
    await self.handle_stream(comm=comm, extra={"worker": worker})
  File "/opt/conda/lib/python3.8/site-packages/distributed/core.py", line 571, in handle_stream
    handler(**merge(extra, msg))
  File "/opt/conda/lib/python3.8/site-packages/distributed/scheduler.py", line 5089, in handle_release_data
    ws: WorkerState = parent._workers_dv[worker]
KeyError: 'tcp://131.225.206.177:10000'
distributed.core - ERROR - 'tcp://131.225.189.73:10000'
Traceback (most recent call last):
  File "/opt/conda/lib/python3.8/site-packages/distributed/core.py", line 571, in handle_stream
    handler(**merge(extra, msg))
  File "/opt/conda/lib/python3.8/site-packages/distributed/scheduler.py", line 5089, in handle_release_data
    ws: WorkerState = parent._workers_dv[worker]
KeyError: 'tcp://131.225.189.73:10000'
distributed.utils - ERROR - 'tcp://131.225.189.73:10000'
Traceback (most recent call last):
  File "/opt/conda/lib/python3.8/site-packages/distributed/utils.py", line 650, in log_errors
    yield
  File "/opt/conda/lib/python3.8/site-packages/distributed/scheduler.py", line 4099, in add_worker
    await self.handle_worker(comm=comm, worker=address)
  File "/opt/conda/lib/python3.8/site-packages/distributed/scheduler.py", line 5189, in handle_worker
    await self.handle_stream(comm=comm, extra={"worker": worker})
  File "/opt/conda/lib/python3.8/site-packages/distributed/core.py", line 571, in handle_stream
    handler(**merge(extra, msg))
  File "/opt/conda/lib/python3.8/site-packages/distributed/scheduler.py", line 5089, in handle_release_data
    ws: WorkerState = parent._workers_dv[worker]
KeyError: 'tcp://131.225.189.73:10000'
distributed.core - ERROR - Exception while handling op register-worker
Traceback (most recent call last):
  File "/opt/conda/lib/python3.8/site-packages/distributed/core.py", line 498, in handle_comm
    result = await result
  File "/opt/conda/lib/python3.8/site-packages/distributed/scheduler.py", line 4099, in add_worker
    await self.handle_worker(comm=comm, worker=address)
  File "/opt/conda/lib/python3.8/site-packages/distributed/scheduler.py", line 5189, in handle_worker
    await self.handle_stream(comm=comm, extra={"worker": worker})
  File "/opt/conda/lib/python3.8/site-packages/distributed/core.py", line 571, in handle_stream
    handler(**merge(extra, msg))
  File "/opt/conda/lib/python3.8/site-packages/distributed/scheduler.py", line 5089, in handle_release_data
    ws: WorkerState = parent._workers_dv[worker]
KeyError: 'tcp://131.225.204.101:10000'
distributed.core - ERROR - Exception while handling op register-worker
Traceback (most recent call last):
  File "/opt/conda/lib/python3.8/site-packages/distributed/core.py", line 498, in handle_comm
    result = await result
  File "/opt/conda/lib/python3.8/site-packages/distributed/scheduler.py", line 4099, in add_worker
    await self.handle_worker(comm=comm, worker=address)
  File "/opt/conda/lib/python3.8/site-packages/distributed/scheduler.py", line 5189, in handle_worker
    await self.handle_stream(comm=comm, extra={"worker": worker})
  File "/opt/conda/lib/python3.8/site-packages/distributed/core.py", line 571, in handle_stream
    handler(**merge(extra, msg))
  File "/opt/conda/lib/python3.8/site-packages/distributed/scheduler.py", line 5089, in handle_release_data
    ws: WorkerState = parent._workers_dv[worker]
KeyError: 'tcp://131.225.191.137:10000'
distributed.core - ERROR - Exception while handling op register-worker
Traceback (most recent call last):
  File "/opt/conda/lib/python3.8/site-packages/distributed/core.py", line 498, in handle_comm
    result = await result
  File "/opt/conda/lib/python3.8/site-packages/distributed/scheduler.py", line 4099, in add_worker
    await self.handle_worker(comm=comm, worker=address)
  File "/opt/conda/lib/python3.8/site-packages/distributed/scheduler.py", line 5189, in handle_worker
    await self.handle_stream(comm=comm, extra={"worker": worker})
  File "/opt/conda/lib/python3.8/site-packages/distributed/core.py", line 571, in handle_stream
    handler(**merge(extra, msg))
  File "/opt/conda/lib/python3.8/site-packages/distributed/scheduler.py", line 5089, in handle_release_data
    ws: WorkerState = parent._workers_dv[worker]
KeyError: 'tcp://131.225.206.197:10000'
distributed.core - ERROR - Exception while handling op register-worker
Traceback (most recent call last):
  File "/opt/conda/lib/python3.8/site-packages/distributed/core.py", line 498, in handle_comm
    result = await result
  File "/opt/conda/lib/python3.8/site-packages/distributed/scheduler.py", line 4099, in add_worker
    await self.handle_worker(comm=comm, worker=address)
  File "/opt/conda/lib/python3.8/site-packages/distributed/scheduler.py", line 5189, in handle_worker
    await self.handle_stream(comm=comm, extra={"worker": worker})
  File "/opt/conda/lib/python3.8/site-packages/distributed/core.py", line 571, in handle_stream
    handler(**merge(extra, msg))
  File "/opt/conda/lib/python3.8/site-packages/distributed/scheduler.py", line 5089, in handle_release_data
    ws: WorkerState = parent._workers_dv[worker]
KeyError: 'tcp://131.225.204.82:10000'
distributed.core - ERROR - Exception while handling op register-worker
Traceback (most recent call last):
  File "/opt/conda/lib/python3.8/site-packages/distributed/core.py", line 498, in handle_comm
    result = await result
  File "/opt/conda/lib/python3.8/site-packages/distributed/scheduler.py", line 4099, in add_worker
    await self.handle_worker(comm=comm, worker=address)
  File "/opt/conda/lib/python3.8/site-packages/distributed/scheduler.py", line 5189, in handle_worker
    await self.handle_stream(comm=comm, extra={"worker": worker})
  File "/opt/conda/lib/python3.8/site-packages/distributed/core.py", line 571, in handle_stream
    handler(**merge(extra, msg))
  File "/opt/conda/lib/python3.8/site-packages/distributed/scheduler.py", line 5089, in handle_release_data
    ws: WorkerState = parent._workers_dv[worker]
KeyError: 'tcp://131.225.204.55:10000'
distributed.core - ERROR - Exception while handling op register-worker
Traceback (most recent call last):
  File "/opt/conda/lib/python3.8/site-packages/distributed/core.py", line 498, in handle_comm
    result = await result
  File "/opt/conda/lib/python3.8/site-packages/distributed/scheduler.py", line 4099, in add_worker
    await self.handle_worker(comm=comm, worker=address)
  File "/opt/conda/lib/python3.8/site-packages/distributed/scheduler.py", line 5189, in handle_worker
    await self.handle_stream(comm=comm, extra={"worker": worker})
  File "/opt/conda/lib/python3.8/site-packages/distributed/core.py", line 571, in handle_stream
    handler(**merge(extra, msg))
  File "/opt/conda/lib/python3.8/site-packages/distributed/scheduler.py", line 5089, in handle_release_data
    ws: WorkerState = parent._workers_dv[worker]
KeyError: 'tcp://131.225.206.38:10000'
distributed.core - ERROR - Exception while handling op register-worker
Traceback (most recent call last):
  File "/opt/conda/lib/python3.8/site-packages/distributed/core.py", line 498, in handle_comm
    result = await result
  File "/opt/conda/lib/python3.8/site-packages/distributed/scheduler.py", line 4099, in add_worker
    await self.handle_worker(comm=comm, worker=address)
  File "/opt/conda/lib/python3.8/site-packages/distributed/scheduler.py", line 5189, in handle_worker
    await self.handle_stream(comm=comm, extra={"worker": worker})
  File "/opt/conda/lib/python3.8/site-packages/distributed/core.py", line 571, in handle_stream
    handler(**merge(extra, msg))
  File "/opt/conda/lib/python3.8/site-packages/distributed/scheduler.py", line 5089, in handle_release_data
    ws: WorkerState = parent._workers_dv[worker]
KeyError: 'tcp://131.225.206.48:10000'
distributed.core - ERROR - Exception while handling op register-worker
Traceback (most recent call last):
  File "/opt/conda/lib/python3.8/site-packages/distributed/core.py", line 498, in handle_comm
    result = await result
  File "/opt/conda/lib/python3.8/site-packages/distributed/scheduler.py", line 4099, in add_worker
    await self.handle_worker(comm=comm, worker=address)
  File "/opt/conda/lib/python3.8/site-packages/distributed/scheduler.py", line 5189, in handle_worker
    await self.handle_stream(comm=comm, extra={"worker": worker})
  File "/opt/conda/lib/python3.8/site-packages/distributed/core.py", line 571, in handle_stream
    handler(**merge(extra, msg))
  File "/opt/conda/lib/python3.8/site-packages/distributed/scheduler.py", line 5089, in handle_release_data
    ws: WorkerState = parent._workers_dv[worker]
KeyError: 'tcp://131.225.204.112:10000'
distributed.core - ERROR - Exception while handling op register-worker
Traceback (most recent call last):
  File "/opt/conda/lib/python3.8/site-packages/distributed/core.py", line 498, in handle_comm
    result = await result
  File "/opt/conda/lib/python3.8/site-packages/distributed/scheduler.py", line 4099, in add_worker
    await self.handle_worker(comm=comm, worker=address)
  File "/opt/conda/lib/python3.8/site-packages/distributed/scheduler.py", line 5189, in handle_worker
    await self.handle_stream(comm=comm, extra={"worker": worker})
  File "/opt/conda/lib/python3.8/site-packages/distributed/core.py", line 571, in handle_stream
    handler(**merge(extra, msg))
  File "/opt/conda/lib/python3.8/site-packages/distributed/scheduler.py", line 5089, in handle_release_data
    ws: WorkerState = parent._workers_dv[worker]
KeyError: 'tcp://131.225.206.177:10000'
distributed.core - ERROR - Exception while handling op register-worker
Traceback (most recent call last):
  File "/opt/conda/lib/python3.8/site-packages/distributed/core.py", line 498, in handle_comm
    result = await result
  File "/opt/conda/lib/python3.8/site-packages/distributed/scheduler.py", line 4099, in add_worker
    await self.handle_worker(comm=comm, worker=address)
  File "/opt/conda/lib/python3.8/site-packages/distributed/scheduler.py", line 5189, in handle_worker
    await self.handle_stream(comm=comm, extra={"worker": worker})
  File "/opt/conda/lib/python3.8/site-packages/distributed/core.py", line 571, in handle_stream
    handler(**merge(extra, msg))
  File "/opt/conda/lib/python3.8/site-packages/distributed/scheduler.py", line 5089, in handle_release_data
    ws: WorkerState = parent._workers_dv[worker]
KeyError: 'tcp://131.225.189.73:10000'
tornado.application - ERROR - Exception in callback functools.partial(<function TCPServer._handle_connection.<locals>.<lambda> at 0x7f6c4957d3a0>, <Task finished name='Task-721' coro=<BaseTCPListener._handle_stream() done, defined at /opt/conda/lib/python3.8/site-packages/distributed/comm/tcp.py:476> exception=KeyError('tcp://131.225.204.101:10000')>)
Traceback (most recent call last):
  File "/opt/conda/lib/python3.8/site-packages/tornado/ioloop.py", line 741, in _run_callback
    ret = callback()
  File "/opt/conda/lib/python3.8/site-packages/tornado/tcpserver.py", line 331, in <lambda>
    gen.convert_yielded(future), lambda f: f.result()
  File "/opt/conda/lib/python3.8/site-packages/distributed/comm/tcp.py", line 493, in _handle_stream
    await self.comm_handler(comm)
  File "/opt/conda/lib/python3.8/site-packages/distributed/core.py", line 498, in handle_comm
    result = await result
  File "/opt/conda/lib/python3.8/site-packages/distributed/scheduler.py", line 4099, in add_worker
    await self.handle_worker(comm=comm, worker=address)
  File "/opt/conda/lib/python3.8/site-packages/distributed/scheduler.py", line 5189, in handle_worker
    await self.handle_stream(comm=comm, extra={"worker": worker})
  File "/opt/conda/lib/python3.8/site-packages/distributed/core.py", line 571, in handle_stream
    handler(**merge(extra, msg))
  File "/opt/conda/lib/python3.8/site-packages/distributed/scheduler.py", line 5089, in handle_release_data
    ws: WorkerState = parent._workers_dv[worker]
KeyError: 'tcp://131.225.204.101:10000'
tornado.application - ERROR - Exception in callback functools.partial(<function TCPServer._handle_connection.<locals>.<lambda> at 0x7f6c49630310>, <Task finished name='Task-760' coro=<BaseTCPListener._handle_stream() done, defined at /opt/conda/lib/python3.8/site-packages/distributed/comm/tcp.py:476> exception=KeyError('tcp://131.225.191.137:10000')>)
Traceback (most recent call last):
  File "/opt/conda/lib/python3.8/site-packages/tornado/ioloop.py", line 741, in _run_callback
    ret = callback()
  File "/opt/conda/lib/python3.8/site-packages/tornado/tcpserver.py", line 331, in <lambda>
    gen.convert_yielded(future), lambda f: f.result()
  File "/opt/conda/lib/python3.8/site-packages/distributed/comm/tcp.py", line 493, in _handle_stream
    await self.comm_handler(comm)
  File "/opt/conda/lib/python3.8/site-packages/distributed/core.py", line 498, in handle_comm
    result = await result
  File "/opt/conda/lib/python3.8/site-packages/distributed/scheduler.py", line 4099, in add_worker
    await self.handle_worker(comm=comm, worker=address)
  File "/opt/conda/lib/python3.8/site-packages/distributed/scheduler.py", line 5189, in handle_worker
    await self.handle_stream(comm=comm, extra={"worker": worker})
  File "/opt/conda/lib/python3.8/site-packages/distributed/core.py", line 571, in handle_stream
    handler(**merge(extra, msg))
  File "/opt/conda/lib/python3.8/site-packages/distributed/scheduler.py", line 5089, in handle_release_data
    ws: WorkerState = parent._workers_dv[worker]
KeyError: 'tcp://131.225.191.137:10000'
tornado.application - ERROR - Exception in callback functools.partial(<function TCPServer._handle_connection.<locals>.<lambda> at 0x7f6c495efca0>, <Task finished name='Task-728' coro=<BaseTCPListener._handle_stream() done, defined at /opt/conda/lib/python3.8/site-packages/distributed/comm/tcp.py:476> exception=KeyError('tcp://131.225.206.197:10000')>)
Traceback (most recent call last):
  File "/opt/conda/lib/python3.8/site-packages/tornado/ioloop.py", line 741, in _run_callback
    ret = callback()
  File "/opt/conda/lib/python3.8/site-packages/tornado/tcpserver.py", line 331, in <lambda>
    gen.convert_yielded(future), lambda f: f.result()
  File "/opt/conda/lib/python3.8/site-packages/distributed/comm/tcp.py", line 493, in _handle_stream
    await self.comm_handler(comm)
  File "/opt/conda/lib/python3.8/site-packages/distributed/core.py", line 498, in handle_comm
    result = await result
  File "/opt/conda/lib/python3.8/site-packages/distributed/scheduler.py", line 4099, in add_worker
    await self.handle_worker(comm=comm, worker=address)
  File "/opt/conda/lib/python3.8/site-packages/distributed/scheduler.py", line 5189, in handle_worker
    await self.handle_stream(comm=comm, extra={"worker": worker})
  File "/opt/conda/lib/python3.8/site-packages/distributed/core.py", line 571, in handle_stream
    handler(**merge(extra, msg))
  File "/opt/conda/lib/python3.8/site-packages/distributed/scheduler.py", line 5089, in handle_release_data
    ws: WorkerState = parent._workers_dv[worker]
KeyError: 'tcp://131.225.206.197:10000'
tornado.application - ERROR - Exception in callback functools.partial(<function TCPServer._handle_connection.<locals>.<lambda> at 0x7f6c495efee0>, <Task finished name='Task-725' coro=<BaseTCPListener._handle_stream() done, defined at /opt/conda/lib/python3.8/site-packages/distributed/comm/tcp.py:476> exception=KeyError('tcp://131.225.204.82:10000')>)
Traceback (most recent call last):
  File "/opt/conda/lib/python3.8/site-packages/tornado/ioloop.py", line 741, in _run_callback
    ret = callback()
  File "/opt/conda/lib/python3.8/site-packages/tornado/tcpserver.py", line 331, in <lambda>
    gen.convert_yielded(future), lambda f: f.result()
  File "/opt/conda/lib/python3.8/site-packages/distributed/comm/tcp.py", line 493, in _handle_stream
    await self.comm_handler(comm)
  File "/opt/conda/lib/python3.8/site-packages/distributed/core.py", line 498, in handle_comm
    result = await result
  File "/opt/conda/lib/python3.8/site-packages/distributed/scheduler.py", line 4099, in add_worker
    await self.handle_worker(comm=comm, worker=address)
  File "/opt/conda/lib/python3.8/site-packages/distributed/scheduler.py", line 5189, in handle_worker
    await self.handle_stream(comm=comm, extra={"worker": worker})
  File "/opt/conda/lib/python3.8/site-packages/distributed/core.py", line 571, in handle_stream
    handler(**merge(extra, msg))
  File "/opt/conda/lib/python3.8/site-packages/distributed/scheduler.py", line 5089, in handle_release_data
    ws: WorkerState = parent._workers_dv[worker]
KeyError: 'tcp://131.225.204.82:10000'
tornado.application - ERROR - Exception in callback functools.partial(<function TCPServer._handle_connection.<locals>.<lambda> at 0x7f6c49557b80>, <Task finished name='Task-939' coro=<BaseTCPListener._handle_stream() done, defined at /opt/conda/lib/python3.8/site-packages/distributed/comm/tcp.py:476> exception=KeyError('tcp://131.225.204.55:10000')>)
Traceback (most recent call last):
  File "/opt/conda/lib/python3.8/site-packages/tornado/ioloop.py", line 741, in _run_callback
    ret = callback()
  File "/opt/conda/lib/python3.8/site-packages/tornado/tcpserver.py", line 331, in <lambda>
    gen.convert_yielded(future), lambda f: f.result()
  File "/opt/conda/lib/python3.8/site-packages/distributed/comm/tcp.py", line 493, in _handle_stream
    await self.comm_handler(comm)
  File "/opt/conda/lib/python3.8/site-packages/distributed/core.py", line 498, in handle_comm
    result = await result
  File "/opt/conda/lib/python3.8/site-packages/distributed/scheduler.py", line 4099, in add_worker
    await self.handle_worker(comm=comm, worker=address)
  File "/opt/conda/lib/python3.8/site-packages/distributed/scheduler.py", line 5189, in handle_worker
    await self.handle_stream(comm=comm, extra={"worker": worker})
  File "/opt/conda/lib/python3.8/site-packages/distributed/core.py", line 571, in handle_stream
    handler(**merge(extra, msg))
  File "/opt/conda/lib/python3.8/site-packages/distributed/scheduler.py", line 5089, in handle_release_data
    ws: WorkerState = parent._workers_dv[worker]
KeyError: 'tcp://131.225.204.55:10000'
tornado.application - ERROR - Exception in callback functools.partial(<function TCPServer._handle_connection.<locals>.<lambda> at 0x7f6c4957d430>, <Task finished name='Task-722' coro=<BaseTCPListener._handle_stream() done, defined at /opt/conda/lib/python3.8/site-packages/distributed/comm/tcp.py:476> exception=KeyError('tcp://131.225.206.38:10000')>)
Traceback (most recent call last):
  File "/opt/conda/lib/python3.8/site-packages/tornado/ioloop.py", line 741, in _run_callback
    ret = callback()
  File "/opt/conda/lib/python3.8/site-packages/tornado/tcpserver.py", line 331, in <lambda>
    gen.convert_yielded(future), lambda f: f.result()
  File "/opt/conda/lib/python3.8/site-packages/distributed/comm/tcp.py", line 493, in _handle_stream
    await self.comm_handler(comm)
  File "/opt/conda/lib/python3.8/site-packages/distributed/core.py", line 498, in handle_comm
    result = await result
  File "/opt/conda/lib/python3.8/site-packages/distributed/scheduler.py", line 4099, in add_worker
    await self.handle_worker(comm=comm, worker=address)
  File "/opt/conda/lib/python3.8/site-packages/distributed/scheduler.py", line 5189, in handle_worker
    await self.handle_stream(comm=comm, extra={"worker": worker})
  File "/opt/conda/lib/python3.8/site-packages/distributed/core.py", line 571, in handle_stream
    handler(**merge(extra, msg))
  File "/opt/conda/lib/python3.8/site-packages/distributed/scheduler.py", line 5089, in handle_release_data
    ws: WorkerState = parent._workers_dv[worker]
KeyError: 'tcp://131.225.206.38:10000'
tornado.application - ERROR - Exception in callback functools.partial(<function TCPServer._handle_connection.<locals>.<lambda> at 0x7f6c49557820>, <Task finished name='Task-942' coro=<BaseTCPListener._handle_stream() done, defined at /opt/conda/lib/python3.8/site-packages/distributed/comm/tcp.py:476> exception=KeyError('tcp://131.225.206.48:10000')>)
Traceback (most recent call last):
  File "/opt/conda/lib/python3.8/site-packages/tornado/ioloop.py", line 741, in _run_callback
    ret = callback()
  File "/opt/conda/lib/python3.8/site-packages/tornado/tcpserver.py", line 331, in <lambda>
    gen.convert_yielded(future), lambda f: f.result()
  File "/opt/conda/lib/python3.8/site-packages/distributed/comm/tcp.py", line 493, in _handle_stream
    await self.comm_handler(comm)
  File "/opt/conda/lib/python3.8/site-packages/distributed/core.py", line 498, in handle_comm
    result = await result
  File "/opt/conda/lib/python3.8/site-packages/distributed/scheduler.py", line 4099, in add_worker
    await self.handle_worker(comm=comm, worker=address)
  File "/opt/conda/lib/python3.8/site-packages/distributed/scheduler.py", line 5189, in handle_worker
    await self.handle_stream(comm=comm, extra={"worker": worker})
  File "/opt/conda/lib/python3.8/site-packages/distributed/core.py", line 571, in handle_stream
    handler(**merge(extra, msg))
  File "/opt/conda/lib/python3.8/site-packages/distributed/scheduler.py", line 5089, in handle_release_data
    ws: WorkerState = parent._workers_dv[worker]
KeyError: 'tcp://131.225.206.48:10000'
tornado.application - ERROR - Exception in callback functools.partial(<function TCPServer._handle_connection.<locals>.<lambda> at 0x7f6c49557a60>, <Task finished name='Task-940' coro=<BaseTCPListener._handle_stream() done, defined at /opt/conda/lib/python3.8/site-packages/distributed/comm/tcp.py:476> exception=KeyError('tcp://131.225.204.112:10000')>)
Traceback (most recent call last):
  File "/opt/conda/lib/python3.8/site-packages/tornado/ioloop.py", line 741, in _run_callback
    ret = callback()
  File "/opt/conda/lib/python3.8/site-packages/tornado/tcpserver.py", line 331, in <lambda>
    gen.convert_yielded(future), lambda f: f.result()
  File "/opt/conda/lib/python3.8/site-packages/distributed/comm/tcp.py", line 493, in _handle_stream
    await self.comm_handler(comm)
  File "/opt/conda/lib/python3.8/site-packages/distributed/core.py", line 498, in handle_comm
    result = await result
  File "/opt/conda/lib/python3.8/site-packages/distributed/scheduler.py", line 4099, in add_worker
    await self.handle_worker(comm=comm, worker=address)
  File "/opt/conda/lib/python3.8/site-packages/distributed/scheduler.py", line 5189, in handle_worker
    await self.handle_stream(comm=comm, extra={"worker": worker})
  File "/opt/conda/lib/python3.8/site-packages/distributed/core.py", line 571, in handle_stream
    handler(**merge(extra, msg))
  File "/opt/conda/lib/python3.8/site-packages/distributed/scheduler.py", line 5089, in handle_release_data
    ws: WorkerState = parent._workers_dv[worker]
KeyError: 'tcp://131.225.204.112:10000'
tornado.application - ERROR - Exception in callback functools.partial(<function TCPServer._handle_connection.<locals>.<lambda> at 0x7f6c49624f70>, <Task finished name='Task-758' coro=<BaseTCPListener._handle_stream() done, defined at /opt/conda/lib/python3.8/site-packages/distributed/comm/tcp.py:476> exception=KeyError('tcp://131.225.206.177:10000')>)
Traceback (most recent call last):
  File "/opt/conda/lib/python3.8/site-packages/tornado/ioloop.py", line 741, in _run_callback
    ret = callback()
  File "/opt/conda/lib/python3.8/site-packages/tornado/tcpserver.py", line 331, in <lambda>
    gen.convert_yielded(future), lambda f: f.result()
  File "/opt/conda/lib/python3.8/site-packages/distributed/comm/tcp.py", line 493, in _handle_stream
    await self.comm_handler(comm)
  File "/opt/conda/lib/python3.8/site-packages/distributed/core.py", line 498, in handle_comm
    result = await result
  File "/opt/conda/lib/python3.8/site-packages/distributed/scheduler.py", line 4099, in add_worker
    await self.handle_worker(comm=comm, worker=address)
  File "/opt/conda/lib/python3.8/site-packages/distributed/scheduler.py", line 5189, in handle_worker
    await self.handle_stream(comm=comm, extra={"worker": worker})
  File "/opt/conda/lib/python3.8/site-packages/distributed/core.py", line 571, in handle_stream
    handler(**merge(extra, msg))
  File "/opt/conda/lib/python3.8/site-packages/distributed/scheduler.py", line 5089, in handle_release_data
    ws: WorkerState = parent._workers_dv[worker]
KeyError: 'tcp://131.225.206.177:10000'
tornado.application - ERROR - Exception in callback functools.partial(<function TCPServer._handle_connection.<locals>.<lambda> at 0x7f6c49624430>, <Task finished name='Task-912' coro=<BaseTCPListener._handle_stream() done, defined at /opt/conda/lib/python3.8/site-packages/distributed/comm/tcp.py:476> exception=KeyError('tcp://131.225.189.73:10000')>)
Traceback (most recent call last):
  File "/opt/conda/lib/python3.8/site-packages/tornado/ioloop.py", line 741, in _run_callback
    ret = callback()
  File "/opt/conda/lib/python3.8/site-packages/tornado/tcpserver.py", line 331, in <lambda>
    gen.convert_yielded(future), lambda f: f.result()
  File "/opt/conda/lib/python3.8/site-packages/distributed/comm/tcp.py", line 493, in _handle_stream
    await self.comm_handler(comm)
  File "/opt/conda/lib/python3.8/site-packages/distributed/core.py", line 498, in handle_comm
    result = await result
  File "/opt/conda/lib/python3.8/site-packages/distributed/scheduler.py", line 4099, in add_worker
    await self.handle_worker(comm=comm, worker=address)
  File "/opt/conda/lib/python3.8/site-packages/distributed/scheduler.py", line 5189, in handle_worker
    await self.handle_stream(comm=comm, extra={"worker": worker})
  File "/opt/conda/lib/python3.8/site-packages/distributed/core.py", line 571, in handle_stream
    handler(**merge(extra, msg))
  File "/opt/conda/lib/python3.8/site-packages/distributed/scheduler.py", line 5089, in handle_release_data
    ws: WorkerState = parent._workers_dv[worker]
KeyError: 'tcp://131.225.189.73:10000'
Traceback (most recent call last):
  File "calcJetHTTriggerEfficiencies.py", line 107, in <module>
    out, metrics = processor.run_uproot_job(
  File "/opt/conda/lib/python3.8/site-packages/coffea/processor/executor.py", line 1385, in run_uproot_job
    out = pre_executor(to_get, metadata_fetcher, out, **pre_args)
  File "/opt/conda/lib/python3.8/site-packages/coffea/processor/executor.py", line 907, in dask_executor
    [work.result() if clevel is None else _decompress(work.result())],
  File "/opt/conda/lib/python3.8/site-packages/distributed/client.py", line 227, in result
    raise exc.with_traceback(tb)
distributed.scheduler.KilledWorker: ('_get_metadata-36964830-d925-4062-bc5f-b89e43cb1bad-1997', <WorkerState 'tcp://131.225.206.221:10000', name: 237, memory: 0, processing: 2>)
Exception in callback BaseAsyncIOLoop._handle_events(16, 1)
handle: <Handle BaseAsyncIOLoop._handle_events(16, 1)>
Traceback (most recent call last):
  File "/opt/conda/lib/python3.8/asyncio/events.py", line 81, in _run
    self._context.run(self._callback, *self._args)
  File "/opt/conda/lib/python3.8/site-packages/tornado/platform/asyncio.py", line 189, in _handle_events
    handler_func(fileobj, events)
  File "/opt/conda/lib/python3.8/site-packages/tornado/netutil.py", line 266, in accept_handler
    connection, address = sock.accept()
  File "/opt/conda/lib/python3.8/socket.py", line 292, in accept
    fd, addr = self._accept()
OSError: [Errno 24] Too many open files
distributed.core - ERROR - 'tcp://131.225.191.254:10000'
Traceback (most recent call last):
  File "/opt/conda/lib/python3.8/site-packages/distributed/core.py", line 571, in handle_stream
    handler(**merge(extra, msg))
  File "/opt/conda/lib/python3.8/site-packages/distributed/scheduler.py", line 5089, in handle_release_data
    ws: WorkerState = parent._workers_dv[worker]
KeyError: 'tcp://131.225.191.254:10000'
distributed.utils - ERROR - 'tcp://131.225.191.254:10000'
Traceback (most recent call last):
  File "/opt/conda/lib/python3.8/site-packages/distributed/utils.py", line 650, in log_errors
    yield
  File "/opt/conda/lib/python3.8/site-packages/distributed/scheduler.py", line 4099, in add_worker
    await self.handle_worker(comm=comm, worker=address)
  File "/opt/conda/lib/python3.8/site-packages/distributed/scheduler.py", line 5189, in handle_worker
    await self.handle_stream(comm=comm, extra={"worker": worker})
  File "/opt/conda/lib/python3.8/site-packages/distributed/core.py", line 571, in handle_stream
    handler(**merge(extra, msg))
  File "/opt/conda/lib/python3.8/site-packages/distributed/scheduler.py", line 5089, in handle_release_data
    ws: WorkerState = parent._workers_dv[worker]
KeyError: 'tcp://131.225.191.254:10000'
Exception in callback BaseAsyncIOLoop._handle_events(16, 1)
handle: <Handle BaseAsyncIOLoop._handle_events(16, 1)>
Traceback (most recent call last):
  File "/opt/conda/lib/python3.8/asyncio/events.py", line 81, in _run
    self._context.run(self._callback, *self._args)
  File "/opt/conda/lib/python3.8/site-packages/tornado/platform/asyncio.py", line 189, in _handle_events
    handler_func(fileobj, events)
  File "/opt/conda/lib/python3.8/site-packages/tornado/netutil.py", line 266, in accept_handler
    connection, address = sock.accept()
  File "/opt/conda/lib/python3.8/socket.py", line 292, in accept
    fd, addr = self._accept()
OSError: [Errno 24] Too many open files
distributed.scheduler - ERROR - Error in reevaluate occupancy
Traceback (most recent call last):
  File "/opt/conda/lib/python3.8/site-packages/psutil/_common.py", line 447, in wrapper
    ret = self._cache[fun]
AttributeError: _cache

During handling of the above exception, another exception occurred:

Traceback (most recent call last):
  File "/opt/conda/lib/python3.8/site-packages/distributed/scheduler.py", line 7090, in reevaluate_occupancy
    if self.proc.cpu_percent() < 50:
  File "/opt/conda/lib/python3.8/site-packages/psutil/__init__.py", line 995, in cpu_percent
    pt2 = self._proc.cpu_times()
  File "/opt/conda/lib/python3.8/site-packages/psutil/_pslinux.py", line 1576, in wrapper
    return fun(self, *args, **kwargs)
  File "/opt/conda/lib/python3.8/site-packages/psutil/_pslinux.py", line 1769, in cpu_times
    values = self._parse_stat_file()
  File "/opt/conda/lib/python3.8/site-packages/psutil/_pslinux.py", line 1576, in wrapper
    return fun(self, *args, **kwargs)
  File "/opt/conda/lib/python3.8/site-packages/psutil/_common.py", line 450, in wrapper
    return fun(self)
  File "/opt/conda/lib/python3.8/site-packages/psutil/_pslinux.py", line 1618, in _parse_stat_file
    with open_binary("%s/%s/stat" % (self._procfs_path, self.pid)) as f:
  File "/opt/conda/lib/python3.8/site-packages/psutil/_common.py", line 711, in open_binary
    return open(fname, "rb", **kwargs)
OSError: [Errno 24] Too many open files: '/proc/27824/stat'
tornado.application - ERROR - Exception in callback functools.partial(<bound method Scheduler.reevaluate_occupancy of <Scheduler: "tcp://131.225.189.182:10034" workers: 171 cores: 171, tasks: 3798>>, worker_index=44)
Traceback (most recent call last):
  File "/opt/conda/lib/python3.8/site-packages/psutil/_common.py", line 447, in wrapper
    ret = self._cache[fun]
AttributeError: _cache

During handling of the above exception, another exception occurred:

Traceback (most recent call last):
  File "/opt/conda/lib/python3.8/site-packages/tornado/ioloop.py", line 741, in _run_callback
    ret = callback()
  File "/opt/conda/lib/python3.8/site-packages/distributed/scheduler.py", line 7090, in reevaluate_occupancy
    if self.proc.cpu_percent() < 50:
  File "/opt/conda/lib/python3.8/site-packages/psutil/__init__.py", line 995, in cpu_percent
    pt2 = self._proc.cpu_times()
  File "/opt/conda/lib/python3.8/site-packages/psutil/_pslinux.py", line 1576, in wrapper
    return fun(self, *args, **kwargs)
  File "/opt/conda/lib/python3.8/site-packages/psutil/_pslinux.py", line 1769, in cpu_times
    values = self._parse_stat_file()
  File "/opt/conda/lib/python3.8/site-packages/psutil/_pslinux.py", line 1576, in wrapper
    return fun(self, *args, **kwargs)
  File "/opt/conda/lib/python3.8/site-packages/psutil/_common.py", line 450, in wrapper
    return fun(self)
  File "/opt/conda/lib/python3.8/site-packages/psutil/_pslinux.py", line 1618, in _parse_stat_file
    with open_binary("%s/%s/stat" % (self._procfs_path, self.pid)) as f:
  File "/opt/conda/lib/python3.8/site-packages/psutil/_common.py", line 711, in open_binary
    return open(fname, "rb", **kwargs)
OSError: [Errno 24] Too many open files: '/proc/27824/stat'
tornado.application - ERROR - Exception in callback <bound method SystemMonitor.update of <SystemMonitor: cpu: 104 memory: 343 MB fds: 476>>
Traceback (most recent call last):
  File "/opt/conda/lib/python3.8/site-packages/psutil/_common.py", line 447, in wrapper
    ret = self._cache[fun]
KeyError: <function Process._parse_stat_file at 0x7f6c68f69c10>

During handling of the above exception, another exception occurred:

Traceback (most recent call last):
  File "/opt/conda/lib/python3.8/site-packages/tornado/ioloop.py", line 905, in _run
    return self.callback()
  File "/opt/conda/lib/python3.8/site-packages/distributed/system_monitor.py", line 61, in update
    cpu = self.proc.cpu_percent()
  File "/opt/conda/lib/python3.8/site-packages/psutil/__init__.py", line 995, in cpu_percent
    pt2 = self._proc.cpu_times()
  File "/opt/conda/lib/python3.8/site-packages/psutil/_pslinux.py", line 1576, in wrapper
    return fun(self, *args, **kwargs)
  File "/opt/conda/lib/python3.8/site-packages/psutil/_pslinux.py", line 1769, in cpu_times
    values = self._parse_stat_file()
  File "/opt/conda/lib/python3.8/site-packages/psutil/_pslinux.py", line 1576, in wrapper
    return fun(self, *args, **kwargs)
  File "/opt/conda/lib/python3.8/site-packages/psutil/_common.py", line 454, in wrapper
    ret = self._cache[fun] = fun(self)
  File "/opt/conda/lib/python3.8/site-packages/psutil/_pslinux.py", line 1618, in _parse_stat_file
    with open_binary("%s/%s/stat" % (self._procfs_path, self.pid)) as f:
  File "/opt/conda/lib/python3.8/site-packages/psutil/_common.py", line 711, in open_binary
    return open(fname, "rb", **kwargs)
OSError: [Errno 24] Too many open files: '/proc/27824/stat'
distributed.core - ERROR - Exception while handling op register-worker
Traceback (most recent call last):
  File "/opt/conda/lib/python3.8/site-packages/distributed/core.py", line 498, in handle_comm
    result = await result
  File "/opt/conda/lib/python3.8/site-packages/distributed/scheduler.py", line 4099, in add_worker
    await self.handle_worker(comm=comm, worker=address)
  File "/opt/conda/lib/python3.8/site-packages/distributed/scheduler.py", line 5189, in handle_worker
    await self.handle_stream(comm=comm, extra={"worker": worker})
  File "/opt/conda/lib/python3.8/site-packages/distributed/core.py", line 571, in handle_stream
    handler(**merge(extra, msg))
  File "/opt/conda/lib/python3.8/site-packages/distributed/scheduler.py", line 5089, in handle_release_data
    ws: WorkerState = parent._workers_dv[worker]
KeyError: 'tcp://131.225.191.254:10000'
Exception in callback BaseAsyncIOLoop._handle_events(16, 1)
handle: <Handle BaseAsyncIOLoop._handle_events(16, 1)>
Traceback (most recent call last):
  File "/opt/conda/lib/python3.8/asyncio/events.py", line 81, in _run
    self._context.run(self._callback, *self._args)
  File "/opt/conda/lib/python3.8/site-packages/tornado/platform/asyncio.py", line 189, in _handle_events
    handler_func(fileobj, events)
  File "/opt/conda/lib/python3.8/site-packages/tornado/netutil.py", line 266, in accept_handler
    connection, address = sock.accept()
  File "/opt/conda/lib/python3.8/socket.py", line 292, in accept
    fd, addr = self._accept()
OSError: [Errno 24] Too many open files
tornado.application - ERROR - Exception in callback functools.partial(<function TCPServer._handle_connection.<locals>.<lambda> at 0x7f6c59c99ee0>, <Task finished name='Task-76' coro=<BaseTCPListener._handle_stream() done, defined at /opt/conda/lib/python3.8/site-packages/distributed/comm/tcp.py:476> exception=KeyError('tcp://131.225.191.254:10000')>)
Traceback (most recent call last):
  File "/opt/conda/lib/python3.8/site-packages/tornado/ioloop.py", line 741, in _run_callback
    ret = callback()
  File "/opt/conda/lib/python3.8/site-packages/tornado/tcpserver.py", line 331, in <lambda>
    gen.convert_yielded(future), lambda f: f.result()
  File "/opt/conda/lib/python3.8/site-packages/distributed/comm/tcp.py", line 493, in _handle_stream
    await self.comm_handler(comm)
  File "/opt/conda/lib/python3.8/site-packages/distributed/core.py", line 498, in handle_comm
    result = await result
  File "/opt/conda/lib/python3.8/site-packages/distributed/scheduler.py", line 4099, in add_worker
    await self.handle_worker(comm=comm, worker=address)
  File "/opt/conda/lib/python3.8/site-packages/distributed/scheduler.py", line 5189, in handle_worker
    await self.handle_stream(comm=comm, extra={"worker": worker})
  File "/opt/conda/lib/python3.8/site-packages/distributed/core.py", line 571, in handle_stream
    handler(**merge(extra, msg))
  File "/opt/conda/lib/python3.8/site-packages/distributed/scheduler.py", line 5089, in handle_release_data
    ws: WorkerState = parent._workers_dv[worker]
KeyError: 'tcp://131.225.191.254:10000'
Exception in callback BaseAsyncIOLoop._handle_events(16, 1)
handle: <Handle BaseAsyncIOLoop._handle_events(16, 1)>
Traceback (most recent call last):
  File "/opt/conda/lib/python3.8/asyncio/events.py", line 81, in _run
    self._context.run(self._callback, *self._args)
  File "/opt/conda/lib/python3.8/site-packages/tornado/platform/asyncio.py", line 189, in _handle_events
    handler_func(fileobj, events)
  File "/opt/conda/lib/python3.8/site-packages/tornado/netutil.py", line 266, in accept_handler
    connection, address = sock.accept()
  File "/opt/conda/lib/python3.8/socket.py", line 292, in accept
    fd, addr = self._accept()
OSError: [Errno 24] Too many open files
Exception in callback BaseAsyncIOLoop._handle_events(16, 1)
handle: <Handle BaseAsyncIOLoop._handle_events(16, 1)>
Traceback (most recent call last):
  File "/opt/conda/lib/python3.8/asyncio/events.py", line 81, in _run
    self._context.run(self._callback, *self._args)
  File "/opt/conda/lib/python3.8/site-packages/tornado/platform/asyncio.py", line 189, in _handle_events
    handler_func(fileobj, events)
  File "/opt/conda/lib/python3.8/site-packages/tornado/netutil.py", line 266, in accept_handler
    connection, address = sock.accept()
  File "/opt/conda/lib/python3.8/socket.py", line 292, in accept
    fd, addr = self._accept()
OSError: [Errno 24] Too many open files
tornado.application - ERROR - Exception in callback <bound method SystemMonitor.update of <SystemMonitor: cpu: 104 memory: 343 MB fds: 476>>
Traceback (most recent call last):
  File "/opt/conda/lib/python3.8/site-packages/psutil/_common.py", line 447, in wrapper
    ret = self._cache[fun]
KeyError: <function Process._parse_stat_file at 0x7f6c68f69c10>

During handling of the above exception, another exception occurred:

Traceback (most recent call last):
  File "/opt/conda/lib/python3.8/site-packages/tornado/ioloop.py", line 905, in _run
    return self.callback()
  File "/opt/conda/lib/python3.8/site-packages/distributed/system_monitor.py", line 61, in update
    cpu = self.proc.cpu_percent()
  File "/opt/conda/lib/python3.8/site-packages/psutil/__init__.py", line 995, in cpu_percent
    pt2 = self._proc.cpu_times()
  File "/opt/conda/lib/python3.8/site-packages/psutil/_pslinux.py", line 1576, in wrapper
    return fun(self, *args, **kwargs)
  File "/opt/conda/lib/python3.8/site-packages/psutil/_pslinux.py", line 1769, in cpu_times
    values = self._parse_stat_file()
  File "/opt/conda/lib/python3.8/site-packages/psutil/_pslinux.py", line 1576, in wrapper
    return fun(self, *args, **kwargs)
  File "/opt/conda/lib/python3.8/site-packages/psutil/_common.py", line 454, in wrapper
    ret = self._cache[fun] = fun(self)
  File "/opt/conda/lib/python3.8/site-packages/psutil/_pslinux.py", line 1618, in _parse_stat_file
    with open_binary("%s/%s/stat" % (self._procfs_path, self.pid)) as f:
  File "/opt/conda/lib/python3.8/site-packages/psutil/_common.py", line 711, in open_binary
    return open(fname, "rb", **kwargs)
OSError: [Errno 24] Too many open files: '/proc/27824/stat'
Exception in callback BaseAsyncIOLoop._handle_events(16, 1)
handle: <Handle BaseAsyncIOLoop._handle_events(16, 1)>
Traceback (most recent call last):
  File "/opt/conda/lib/python3.8/asyncio/events.py", line 81, in _run
    self._context.run(self._callback, *self._args)
  File "/opt/conda/lib/python3.8/site-packages/tornado/platform/asyncio.py", line 189, in _handle_events
    handler_func(fileobj, events)
  File "/opt/conda/lib/python3.8/site-packages/tornado/netutil.py", line 266, in accept_handler
    connection, address = sock.accept()
  File "/opt/conda/lib/python3.8/socket.py", line 292, in accept
    fd, addr = self._accept()
OSError: [Errno 24] Too many open files
Exception in callback BaseAsyncIOLoop._handle_events(16, 1)
handle: <Handle BaseAsyncIOLoop._handle_events(16, 1)>
Traceback (most recent call last):
  File "/opt/conda/lib/python3.8/asyncio/events.py", line 81, in _run
    self._context.run(self._callback, *self._args)
  File "/opt/conda/lib/python3.8/site-packages/tornado/platform/asyncio.py", line 189, in _handle_events
    handler_func(fileobj, events)
  File "/opt/conda/lib/python3.8/site-packages/tornado/netutil.py", line 266, in accept_handler
    connection, address = sock.accept()
  File "/opt/conda/lib/python3.8/socket.py", line 292, in accept
    fd, addr = self._accept()
OSError: [Errno 24] Too many open files
tornado.application - ERROR - Exception in callback <bound method SystemMonitor.update of <SystemMonitor: cpu: 104 memory: 343 MB fds: 476>>
Traceback (most recent call last):
  File "/opt/conda/lib/python3.8/site-packages/psutil/_common.py", line 447, in wrapper
    ret = self._cache[fun]
KeyError: <function Process._parse_stat_file at 0x7f6c68f69c10>

During handling of the above exception, another exception occurred:

Traceback (most recent call last):
  File "/opt/conda/lib/python3.8/site-packages/tornado/ioloop.py", line 905, in _run
    return self.callback()
  File "/opt/conda/lib/python3.8/site-packages/distributed/system_monitor.py", line 61, in update
    cpu = self.proc.cpu_percent()
  File "/opt/conda/lib/python3.8/site-packages/psutil/__init__.py", line 995, in cpu_percent
    pt2 = self._proc.cpu_times()
  File "/opt/conda/lib/python3.8/site-packages/psutil/_pslinux.py", line 1576, in wrapper
    return fun(self, *args, **kwargs)
  File "/opt/conda/lib/python3.8/site-packages/psutil/_pslinux.py", line 1769, in cpu_times
    values = self._parse_stat_file()
  File "/opt/conda/lib/python3.8/site-packages/psutil/_pslinux.py", line 1576, in wrapper
    return fun(self, *args, **kwargs)
  File "/opt/conda/lib/python3.8/site-packages/psutil/_common.py", line 454, in wrapper
    ret = self._cache[fun] = fun(self)
  File "/opt/conda/lib/python3.8/site-packages/psutil/_pslinux.py", line 1618, in _parse_stat_file
    with open_binary("%s/%s/stat" % (self._procfs_path, self.pid)) as f:
  File "/opt/conda/lib/python3.8/site-packages/psutil/_common.py", line 711, in open_binary
    return open(fname, "rb", **kwargs)
OSError: [Errno 24] Too many open files: '/proc/27824/stat'
Exception ignored in: <bound method GCDiagnosis._gc_callback of <distributed.utils_perf.GCDiagnosis object at 0x7f6c688d5f10>>
Traceback (most recent call last):
  File "/opt/conda/lib/python3.8/site-packages/distributed/utils_perf.py", line 188, in _gc_callback
  File "/opt/conda/lib/python3.8/site-packages/psutil/_common.py", line 450, in wrapper
  File "/opt/conda/lib/python3.8/site-packages/psutil/__init__.py", line 1054, in memory_info
  File "/opt/conda/lib/python3.8/site-packages/psutil/_pslinux.py", line 1576, in wrapper
  File "/opt/conda/lib/python3.8/site-packages/psutil/_pslinux.py", line 1810, in memory_info
  File "/opt/conda/lib/python3.8/site-packages/psutil/_common.py", line 711, in open_binary
OSError: [Errno 24] Too many open files: '/proc/27824/statm'
Exception ignored in: <bound method GCDiagnosis._gc_callback of <distributed.utils_perf.GCDiagnosis object at 0x7f6c688d5f10>>
Traceback (most recent call last):
  File "/opt/conda/lib/python3.8/site-packages/distributed/utils_perf.py", line 188, in _gc_callback
  File "/opt/conda/lib/python3.8/site-packages/psutil/_common.py", line 450, in wrapper
  File "/opt/conda/lib/python3.8/site-packages/psutil/__init__.py", line 1054, in memory_info
  File "/opt/conda/lib/python3.8/site-packages/psutil/_pslinux.py", line 1576, in wrapper
  File "/opt/conda/lib/python3.8/site-packages/psutil/_pslinux.py", line 1810, in memory_info
  File "/opt/conda/lib/python3.8/site-packages/psutil/_common.py", line 711, in open_binary
OSError: [Errno 24] Too many open files: '/proc/27824/statm'
Exception in callback BaseAsyncIOLoop._handle_events(16, 1)
handle: <Handle BaseAsyncIOLoop._handle_events(16, 1)>
Traceback (most recent call last):
  File "/opt/conda/lib/python3.8/asyncio/events.py", line 81, in _run
    self._context.run(self._callback, *self._args)
  File "/opt/conda/lib/python3.8/site-packages/tornado/platform/asyncio.py", line 189, in _handle_events
    handler_func(fileobj, events)
  File "/opt/conda/lib/python3.8/site-packages/tornado/netutil.py", line 266, in accept_handler
    connection, address = sock.accept()
  File "/opt/conda/lib/python3.8/socket.py", line 292, in accept
    fd, addr = self._accept()
OSError: [Errno 24] Too many open files
Exception in callback BaseAsyncIOLoop._handle_events(16, 1)
handle: <Handle BaseAsyncIOLoop._handle_events(16, 1)>
Traceback (most recent call last):
  File "/opt/conda/lib/python3.8/asyncio/events.py", line 81, in _run
    self._context.run(self._callback, *self._args)
  File "/opt/conda/lib/python3.8/site-packages/tornado/platform/asyncio.py", line 189, in _handle_events
    handler_func(fileobj, events)
  File "/opt/conda/lib/python3.8/site-packages/tornado/netutil.py", line 266, in accept_handler
    connection, address = sock.accept()
  File "/opt/conda/lib/python3.8/socket.py", line 292, in accept
    fd, addr = self._accept()
OSError: [Errno 24] Too many open files
tornado.application - ERROR - Exception in callback <bound method SystemMonitor.update of <SystemMonitor: cpu: 104 memory: 343 MB fds: 476>>
Traceback (most recent call last):
  File "/opt/conda/lib/python3.8/site-packages/psutil/_common.py", line 447, in wrapper
    ret = self._cache[fun]
KeyError: <function Process._parse_stat_file at 0x7f6c68f69c10>

During handling of the above exception, another exception occurred:

Traceback (most recent call last):
  File "/opt/conda/lib/python3.8/site-packages/tornado/ioloop.py", line 905, in _run
    return self.callback()
  File "/opt/conda/lib/python3.8/site-packages/distributed/system_monitor.py", line 61, in update
    cpu = self.proc.cpu_percent()
  File "/opt/conda/lib/python3.8/site-packages/psutil/__init__.py", line 995, in cpu_percent
    pt2 = self._proc.cpu_times()
  File "/opt/conda/lib/python3.8/site-packages/psutil/_pslinux.py", line 1576, in wrapper
    return fun(self, *args, **kwargs)
  File "/opt/conda/lib/python3.8/site-packages/psutil/_pslinux.py", line 1769, in cpu_times
    values = self._parse_stat_file()
  File "/opt/conda/lib/python3.8/site-packages/psutil/_pslinux.py", line 1576, in wrapper
    return fun(self, *args, **kwargs)
  File "/opt/conda/lib/python3.8/site-packages/psutil/_common.py", line 454, in wrapper
    ret = self._cache[fun] = fun(self)
  File "/opt/conda/lib/python3.8/site-packages/psutil/_pslinux.py", line 1618, in _parse_stat_file
    with open_binary("%s/%s/stat" % (self._procfs_path, self.pid)) as f:
  File "/opt/conda/lib/python3.8/site-packages/psutil/_common.py", line 711, in open_binary
    return open(fname, "rb", **kwargs)
OSError: [Errno 24] Too many open files: '/proc/27824/stat'
Exception in callback BaseAsyncIOLoop._handle_events(16, 1)
handle: <Handle BaseAsyncIOLoop._handle_events(16, 1)>
Traceback (most recent call last):
  File "/opt/conda/lib/python3.8/asyncio/events.py", line 81, in _run
    self._context.run(self._callback, *self._args)
  File "/opt/conda/lib/python3.8/site-packages/tornado/platform/asyncio.py", line 189, in _handle_events
    handler_func(fileobj, events)
  File "/opt/conda/lib/python3.8/site-packages/tornado/netutil.py", line 266, in accept_handler
    connection, address = sock.accept()
  File "/opt/conda/lib/python3.8/socket.py", line 292, in accept
    fd, addr = self._accept()
OSError: [Errno 24] Too many open files
Exception in callback BaseAsyncIOLoop._handle_events(16, 1)
handle: <Handle BaseAsyncIOLoop._handle_events(16, 1)>
Traceback (most recent call last):
  File "/opt/conda/lib/python3.8/asyncio/events.py", line 81, in _run
    self._context.run(self._callback, *self._args)
  File "/opt/conda/lib/python3.8/site-packages/tornado/platform/asyncio.py", line 189, in _handle_events
    handler_func(fileobj, events)
  File "/opt/conda/lib/python3.8/site-packages/tornado/netutil.py", line 266, in accept_handler
    connection, address = sock.accept()
  File "/opt/conda/lib/python3.8/socket.py", line 292, in accept
    fd, addr = self._accept()
OSError: [Errno 24] Too many open files
tornado.application - ERROR - Exception in callback <bound method SystemMonitor.update of <SystemMonitor: cpu: 104 memory: 343 MB fds: 476>>
Traceback (most recent call last):
  File "/opt/conda/lib/python3.8/site-packages/psutil/_common.py", line 447, in wrapper
    ret = self._cache[fun]
KeyError: <function Process._parse_stat_file at 0x7f6c68f69c10>

During handling of the above exception, another exception occurred:

Traceback (most recent call last):
  File "/opt/conda/lib/python3.8/site-packages/tornado/ioloop.py", line 905, in _run
    return self.callback()
  File "/opt/conda/lib/python3.8/site-packages/distributed/system_monitor.py", line 61, in update
    cpu = self.proc.cpu_percent()
  File "/opt/conda/lib/python3.8/site-packages/psutil/__init__.py", line 995, in cpu_percent
    pt2 = self._proc.cpu_times()
  File "/opt/conda/lib/python3.8/site-packages/psutil/_pslinux.py", line 1576, in wrapper
    return fun(self, *args, **kwargs)
  File "/opt/conda/lib/python3.8/site-packages/psutil/_pslinux.py", line 1769, in cpu_times
    values = self._parse_stat_file()
  File "/opt/conda/lib/python3.8/site-packages/psutil/_pslinux.py", line 1576, in wrapper
    return fun(self, *args, **kwargs)
  File "/opt/conda/lib/python3.8/site-packages/psutil/_common.py", line 454, in wrapper
    ret = self._cache[fun] = fun(self)
  File "/opt/conda/lib/python3.8/site-packages/psutil/_pslinux.py", line 1618, in _parse_stat_file
    with open_binary("%s/%s/stat" % (self._procfs_path, self.pid)) as f:
  File "/opt/conda/lib/python3.8/site-packages/psutil/_common.py", line 711, in open_binary
    return open(fname, "rb", **kwargs)
OSError: [Errno 24] Too many open files: '/proc/27824/stat'
Exception ignored in: <bound method GCDiagnosis._gc_callback of <distributed.utils_perf.GCDiagnosis object at 0x7f6c688d5f10>>
Traceback (most recent call last):
  File "/opt/conda/lib/python3.8/site-packages/distributed/utils_perf.py", line 188, in _gc_callback
  File "/opt/conda/lib/python3.8/site-packages/psutil/_common.py", line 450, in wrapper
  File "/opt/conda/lib/python3.8/site-packages/psutil/__init__.py", line 1054, in memory_info
  File "/opt/conda/lib/python3.8/site-packages/psutil/_pslinux.py", line 1576, in wrapper
  File "/opt/conda/lib/python3.8/site-packages/psutil/_pslinux.py", line 1810, in memory_info
  File "/opt/conda/lib/python3.8/site-packages/psutil/_common.py", line 711, in open_binary
OSError: [Errno 24] Too many open files: '/proc/27824/statm'
Exception ignored in: <bound method GCDiagnosis._gc_callback of <distributed.utils_perf.GCDiagnosis object at 0x7f6c688d5f10>>
Traceback (most recent call last):
  File "/opt/conda/lib/python3.8/site-packages/distributed/utils_perf.py", line 188, in _gc_callback
  File "/opt/conda/lib/python3.8/site-packages/psutil/_common.py", line 450, in wrapper
  File "/opt/conda/lib/python3.8/site-packages/psutil/__init__.py", line 1054, in memory_info
  File "/opt/conda/lib/python3.8/site-packages/psutil/_pslinux.py", line 1576, in wrapper
  File "/opt/conda/lib/python3.8/site-packages/psutil/_pslinux.py", line 1810, in memory_info
  File "/opt/conda/lib/python3.8/site-packages/psutil/_common.py", line 711, in open_binary
OSError: [Errno 24] Too many open files: '/proc/27824/statm'
Exception in callback BaseAsyncIOLoop._handle_events(16, 1)
handle: <Handle BaseAsyncIOLoop._handle_events(16, 1)>
Traceback (most recent call last):
  File "/opt/conda/lib/python3.8/asyncio/events.py", line 81, in _run
    self._context.run(self._callback, *self._args)
  File "/opt/conda/lib/python3.8/site-packages/tornado/platform/asyncio.py", line 189, in _handle_events
    handler_func(fileobj, events)
  File "/opt/conda/lib/python3.8/site-packages/tornado/netutil.py", line 266, in accept_handler
    connection, address = sock.accept()
  File "/opt/conda/lib/python3.8/socket.py", line 292, in accept
    fd, addr = self._accept()
OSError: [Errno 24] Too many open files
Exception in callback BaseAsyncIOLoop._handle_events(16, 1)
handle: <Handle BaseAsyncIOLoop._handle_events(16, 1)>
Traceback (most recent call last):
  File "/opt/conda/lib/python3.8/asyncio/events.py", line 81, in _run
    self._context.run(self._callback, *self._args)
  File "/opt/conda/lib/python3.8/site-packages/tornado/platform/asyncio.py", line 189, in _handle_events
    handler_func(fileobj, events)
  File "/opt/conda/lib/python3.8/site-packages/tornado/netutil.py", line 266, in accept_handler
    connection, address = sock.accept()
  File "/opt/conda/lib/python3.8/socket.py", line 292, in accept
    fd, addr = self._accept()
OSError: [Errno 24] Too many open files
tornado.application - ERROR - Exception in callback <bound method SystemMonitor.update of <SystemMonitor: cpu: 104 memory: 343 MB fds: 476>>
Traceback (most recent call last):
  File "/opt/conda/lib/python3.8/site-packages/psutil/_common.py", line 447, in wrapper
    ret = self._cache[fun]
KeyError: <function Process._parse_stat_file at 0x7f6c68f69c10>

During handling of the above exception, another exception occurred:

Traceback (most recent call last):
  File "/opt/conda/lib/python3.8/site-packages/tornado/ioloop.py", line 905, in _run
    return self.callback()
  File "/opt/conda/lib/python3.8/site-packages/distributed/system_monitor.py", line 61, in update
    cpu = self.proc.cpu_percent()
  File "/opt/conda/lib/python3.8/site-packages/psutil/__init__.py", line 995, in cpu_percent
    pt2 = self._proc.cpu_times()
  File "/opt/conda/lib/python3.8/site-packages/psutil/_pslinux.py", line 1576, in wrapper
    return fun(self, *args, **kwargs)
  File "/opt/conda/lib/python3.8/site-packages/psutil/_pslinux.py", line 1769, in cpu_times
    values = self._parse_stat_file()
  File "/opt/conda/lib/python3.8/site-packages/psutil/_pslinux.py", line 1576, in wrapper
    return fun(self, *args, **kwargs)
  File "/opt/conda/lib/python3.8/site-packages/psutil/_common.py", line 454, in wrapper
    ret = self._cache[fun] = fun(self)
  File "/opt/conda/lib/python3.8/site-packages/psutil/_pslinux.py", line 1618, in _parse_stat_file
    with open_binary("%s/%s/stat" % (self._procfs_path, self.pid)) as f:
  File "/opt/conda/lib/python3.8/site-packages/psutil/_common.py", line 711, in open_binary
    return open(fname, "rb", **kwargs)
OSError: [Errno 24] Too many open files: '/proc/27824/stat'
Exception in callback BaseAsyncIOLoop._handle_events(16, 1)
handle: <Handle BaseAsyncIOLoop._handle_events(16, 1)>
Traceback (most recent call last):
  File "/opt/conda/lib/python3.8/asyncio/events.py", line 81, in _run
    self._context.run(self._callback, *self._args)
  File "/opt/conda/lib/python3.8/site-packages/tornado/platform/asyncio.py", line 189, in _handle_events
    handler_func(fileobj, events)
  File "/opt/conda/lib/python3.8/site-packages/tornado/netutil.py", line 266, in accept_handler
    connection, address = sock.accept()
  File "/opt/conda/lib/python3.8/socket.py", line 292, in accept
    fd, addr = self._accept()
OSError: [Errno 24] Too many open files
Exception ignored in: <bound method GCDiagnosis._gc_callback of <distributed.utils_perf.GCDiagnosis object at 0x7f6c688d5f10>>
Traceback (most recent call last):
  File "/opt/conda/lib/python3.8/site-packages/distributed/utils_perf.py", line 188, in _gc_callback
  File "/opt/conda/lib/python3.8/site-packages/psutil/_common.py", line 450, in wrapper
  File "/opt/conda/lib/python3.8/site-packages/psutil/__init__.py", line 1054, in memory_info
  File "/opt/conda/lib/python3.8/site-packages/psutil/_pslinux.py", line 1576, in wrapper
  File "/opt/conda/lib/python3.8/site-packages/psutil/_pslinux.py", line 1810, in memory_info
  File "/opt/conda/lib/python3.8/site-packages/psutil/_common.py", line 711, in open_binary
OSError: [Errno 24] Too many open files: '/proc/27824/statm'
Exception ignored in: <bound method GCDiagnosis._gc_callback of <distributed.utils_perf.GCDiagnosis object at 0x7f6c688d5f10>>
Traceback (most recent call last):
  File "/opt/conda/lib/python3.8/site-packages/distributed/utils_perf.py", line 188, in _gc_callback
  File "/opt/conda/lib/python3.8/site-packages/psutil/_common.py", line 450, in wrapper
  File "/opt/conda/lib/python3.8/site-packages/psutil/__init__.py", line 1054, in memory_info
  File "/opt/conda/lib/python3.8/site-packages/psutil/_pslinux.py", line 1576, in wrapper
  File "/opt/conda/lib/python3.8/site-packages/psutil/_pslinux.py", line 1810, in memory_info
  File "/opt/conda/lib/python3.8/site-packages/psutil/_common.py", line 711, in open_binary
OSError: [Errno 24] Too many open files: '/proc/27824/statm'
Exception in callback BaseAsyncIOLoop._handle_events(16, 1)
handle: <Handle BaseAsyncIOLoop._handle_events(16, 1)>
Traceback (most recent call last):
  File "/opt/conda/lib/python3.8/asyncio/events.py", line 81, in _run
    self._context.run(self._callback, *self._args)
  File "/opt/conda/lib/python3.8/site-packages/tornado/platform/asyncio.py", line 189, in _handle_events
    handler_func(fileobj, events)
  File "/opt/conda/lib/python3.8/site-packages/tornado/netutil.py", line 266, in accept_handler
    connection, address = sock.accept()
  File "/opt/conda/lib/python3.8/socket.py", line 292, in accept
    fd, addr = self._accept()
OSError: [Errno 24] Too many open files
